2017-05-23 22:49:34,694 INFO     BEGIN
2017-05-23 22:49:34,694 INFO     struct {
    load: 'minicraft_task_train'
    trainer:
        n_iters: 3000
        n_rollout_batch: 100
        max_rollout_len: 100
        name: 'ImitationTrainer'
        switch_iter: 0
        n_update: 50
        resample_every: 1
        log_each_task: False
    name: 'minicraft_task_eval'
    train: False
    eval: True
    objective:
        discount: 0.97
        entropy_bonus: 0.001
        step_size: 0.001
        n_train_batch: 5000
    world:
        test_fold: 'val'
        name: 'Minicraft2World'
        train_fold: 'train'
    model:
        critic:
            type: 'linear'
            by_task: True
        intrinsic_bonus: 0
        controller:
            param_ling: False
            param_task: True
            train_embeddings: True
            n_embed: 64
        actor:
            n_hidden: [64, 64]
            ret_bias: 0
        name: 'ReprModel'
    experiment_dir: 'experiments/minicraft_task_eval'
}
2017-05-23 22:49:34,694 INFO     [ZERO SHOT EVAL]
2017-05-23 22:49:35,146 ERROR    Uncaught exception: Key ReprModel/null_repr/repr not found in checkpoint
	 [[Node: save/RestoreV2_7 = RestoreV2[dtypes=[DT_FLOAT], _device="/job:localhost/replica:0/task:0/cpu:0"](_recv_save/Const_0, save/RestoreV2_7/tensor_names, save/RestoreV2_7/shape_and_slices)]]

Caused by op u'save/RestoreV2_7', defined at:
  File "main.py", line 100, in <module>
    main()
  File "main.py", line 30, in main
    model = models.load(config, world)
  File "/home/ubuntu/phint/models/__init__.py", line 8, in load
    return cls(config, *args)
  File "/home/ubuntu/phint/models/repr.py", line 161, in __init__
    self.saver = tf.train.Saver()
  File "/home/ubuntu/anaconda2/lib/python2.7/site-packages/tensorflow/python/training/saver.py", line 1051, in __init__
    self.build()
  File "/home/ubuntu/anaconda2/lib/python2.7/site-packages/tensorflow/python/training/saver.py", line 1081, in build
    restore_sequentially=self._restore_sequentially)
  File "/home/ubuntu/anaconda2/lib/python2.7/site-packages/tensorflow/python/training/saver.py", line 675, in build
    restore_sequentially, reshape)
  File "/home/ubuntu/anaconda2/lib/python2.7/site-packages/tensorflow/python/training/saver.py", line 402, in _AddRestoreOps
    tensors = self.restore_op(filename_tensor, saveable, preferred_shard)
  File "/home/ubuntu/anaconda2/lib/python2.7/site-packages/tensorflow/python/training/saver.py", line 242, in restore_op
    [spec.tensor.dtype])[0])
  File "/home/ubuntu/anaconda2/lib/python2.7/site-packages/tensorflow/python/ops/gen_io_ops.py", line 668, in restore_v2
    dtypes=dtypes, name=name)
  File "/home/ubuntu/anaconda2/lib/python2.7/site-packages/tensorflow/python/framework/op_def_library.py", line 763, in apply_op
    op_def=op_def)
  File "/home/ubuntu/anaconda2/lib/python2.7/site-packages/tensorflow/python/framework/ops.py", line 2395, in create_op
    original_op=self._default_original_op, op_def=op_def)
  File "/home/ubuntu/anaconda2/lib/python2.7/site-packages/tensorflow/python/framework/ops.py", line 1264, in __init__
    self._traceback = _extract_stack()

NotFoundError (see above for traceback): Key ReprModel/null_repr/repr not found in checkpoint
	 [[Node: save/RestoreV2_7 = RestoreV2[dtypes=[DT_FLOAT], _device="/job:localhost/replica:0/task:0/cpu:0"](_recv_save/Const_0, save/RestoreV2_7/tensor_names, save/RestoreV2_7/shape_and_slices)]]
None
2017-05-23 22:49:35,148 ERROR    Traceback (most recent call last):

  File "main.py", line 100, in <module>
    main()

  File "main.py", line 70, in main
    _evaluate_full()

  File "main.py", line 57, in _evaluate_full
    zs_evaluator.evaluate()

  File "/home/ubuntu/phint/evaluators/zero_shot.py", line 15, in evaluate
    self.model.load(self.config.load, self.session)

  File "/home/ubuntu/phint/models/repr.py", line 241, in load
    os.path.join("experiments", source, "repr.chk"))

  File "/home/ubuntu/anaconda2/lib/python2.7/site-packages/tensorflow/python/training/saver.py", line 1439, in restore
    {self.saver_def.filename_tensor_name: save_path})

  File "/home/ubuntu/anaconda2/lib/python2.7/site-packages/tensorflow/python/client/session.py", line 767, in run
    run_metadata_ptr)

  File "/home/ubuntu/anaconda2/lib/python2.7/site-packages/tensorflow/python/client/session.py", line 965, in _run
    feed_dict_string, options, run_metadata)

  File "/home/ubuntu/anaconda2/lib/python2.7/site-packages/tensorflow/python/client/session.py", line 1015, in _do_run
    target_list, options, run_metadata)

  File "/home/ubuntu/anaconda2/lib/python2.7/site-packages/tensorflow/python/client/session.py", line 1035, in _do_call
    raise type(e)(node_def, op, message)

NotFoundError: Key ReprModel/null_repr/repr not found in checkpoint
	 [[Node: save/RestoreV2_7 = RestoreV2[dtypes=[DT_FLOAT], _device="/job:localhost/replica:0/task:0/cpu:0"](_recv_save/Const_0, save/RestoreV2_7/tensor_names, save/RestoreV2_7/shape_and_slices)]]

Caused by op u'save/RestoreV2_7', defined at:
  File "main.py", line 100, in <module>
    main()
  File "main.py", line 30, in main
    model = models.load(config, world)
  File "/home/ubuntu/phint/models/__init__.py", line 8, in load
    return cls(config, *args)
  File "/home/ubuntu/phint/models/repr.py", line 161, in __init__
    self.saver = tf.train.Saver()
  File "/home/ubuntu/anaconda2/lib/python2.7/site-packages/tensorflow/python/training/saver.py", line 1051, in __init__
    self.build()
  File "/home/ubuntu/anaconda2/lib/python2.7/site-packages/tensorflow/python/training/saver.py", line 1081, in build
    restore_sequentially=self._restore_sequentially)
  File "/home/ubuntu/anaconda2/lib/python2.7/site-packages/tensorflow/python/training/saver.py", line 675, in build
    restore_sequentially, reshape)
  File "/home/ubuntu/anaconda2/lib/python2.7/site-packages/tensorflow/python/training/saver.py", line 402, in _AddRestoreOps
    tensors = self.restore_op(filename_tensor, saveable, preferred_shard)
  File "/home/ubuntu/anaconda2/lib/python2.7/site-packages/tensorflow/python/training/saver.py", line 242, in restore_op
    [spec.tensor.dtype])[0])
  File "/home/ubuntu/anaconda2/lib/python2.7/site-packages/tensorflow/python/ops/gen_io_ops.py", line 668, in restore_v2
    dtypes=dtypes, name=name)
  File "/home/ubuntu/anaconda2/lib/python2.7/site-packages/tensorflow/python/framework/op_def_library.py", line 763, in apply_op
    op_def=op_def)
  File "/home/ubuntu/anaconda2/lib/python2.7/site-packages/tensorflow/python/framework/ops.py", line 2395, in create_op
    original_op=self._default_original_op, op_def=op_def)
  File "/home/ubuntu/anaconda2/lib/python2.7/site-packages/tensorflow/python/framework/ops.py", line 1264, in __init__
    self._traceback = _extract_stack()

NotFoundError (see above for traceback): Key ReprModel/null_repr/repr not found in checkpoint
	 [[Node: save/RestoreV2_7 = RestoreV2[dtypes=[DT_FLOAT], _device="/job:localhost/replica:0/task:0/cpu:0"](_recv_save/Const_0, save/RestoreV2_7/tensor_names, save/RestoreV2_7/shape_and_slices)]]

None
